MemoryError

During handling of the above exception, another exception occurred:

MemoryError

During handling of the above exception, another exception occurred:

Traceback (most recent call last):
  File "paths_constraints_main.py", line 5, in <module>
  File "/home/ittay.al/venv/pproc/lib/python3.7/site-packages/angr/__init__.py", line 40, in <module>
  File "/home/ittay.al/venv/pproc/lib/python3.7/site-packages/angr/sim_procedure.py", line 520, in <module>
  File "/home/ittay.al/venv/pproc/lib/python3.7/site-packages/angr/sim_type.py", line 1716, in <module>
  File "/home/ittay.al/venv/pproc/lib/python3.7/site-packages/pycparser/ply/yacc.py", line 3432, in yacc
  File "/home/ittay.al/venv/pproc/lib/python3.7/site-packages/pycparser/ply/yacc.py", line 2133, in __init__
  File "/home/ittay.al/venv/pproc/lib/python3.7/site-packages/pycparser/ply/yacc.py", line 2547, in lr_parse_table
MemoryError
