Exception ignored in: <generator object FunctionManager.__iter__ at 0x7fb93158c450>
MemoryError: 
Exception ignored in: <generator object ValuesView.__iter__ at 0x7fb93158cb50>
MemoryError: 
--- Logging error ---
Traceback (most recent call last):
  File "/home/ittay.al/venv/pproc/lib/python3.7/site-packages/angr/analyses/analysis.py", line 157, in _resilience
  File "/home/ittay.al/venv/pproc/lib/python3.7/site-packages/angr/analyses/loopfinder.py", line 54, in __init__
  File "/home/ittay.al/venv/pproc/lib/python3.7/site-packages/angr/analyses/loopfinder.py", line 163, in _parse_loops_from_graph
  File "/home/ittay.al/venv/pproc/lib/python3.7/site-packages/angr/analyses/loopfinder.py", line 163, in <genexpr>
  File "/home/ittay.al/venv/pproc/lib/python3.7/site-packages/networkx/classes/graph.py", line 1543, in copy
  File "/home/ittay.al/venv/pproc/lib/python3.7/site-packages/networkx/classes/digraph.py", line 484, in add_nodes_from
MemoryError

During handling of the above exception, another exception occurred:

Traceback (most recent call last):
  File "/home/ittay.al/miniconda3/envs/tf1/lib/python3.7/contextlib.py", line 130, in __exit__
  File "/home/ittay.al/venv/pproc/lib/python3.7/site-packages/angr/analyses/analysis.py", line 162, in _resilience
MemoryError

During handling of the above exception, another exception occurred:

Traceback (most recent call last):
  File "paths_constraints_main.py", line 212, in analyze_binary
  File "paths_constraints_main.py", line 44, in analyze_func
  File "/home/ittay.al/venv/pproc/lib/python3.7/site-packages/angr/sim_manager.py", line 189, in use_technique
  File "/home/ittay.al/venv/pproc/lib/python3.7/site-packages/angr/exploration_techniques/loop_seer.py", line 80, in setup
  File "/home/ittay.al/venv/pproc/lib/python3.7/site-packages/angr/analyses/analysis.py", line 115, in __call__
MemoryError

During handling of the above exception, another exception occurred:

Traceback (most recent call last):
  File "/home/ittay.al/miniconda3/envs/tf1/lib/python3.7/logging/__init__.py", line 1025, in emit
  File "/home/ittay.al/miniconda3/envs/tf1/lib/python3.7/logging/__init__.py", line 869, in format
  File "/home/ittay.al/miniconda3/envs/tf1/lib/python3.7/logging/__init__.py", line 610, in format
  File "/home/ittay.al/miniconda3/envs/tf1/lib/python3.7/logging/__init__.py", line 550, in formatTime
MemoryError

During handling of the above exception, another exception occurred:

Traceback (most recent call last):
  File "/home/ittay.al/miniconda3/envs/tf1/lib/python3.7/logging/__init__.py", line 1033, in emit
  File "/home/ittay.al/miniconda3/envs/tf1/lib/python3.7/logging/__init__.py", line 947, in handleError
  File "/home/ittay.al/miniconda3/envs/tf1/lib/python3.7/traceback.py", line 104, in print_exception
  File "/home/ittay.al/miniconda3/envs/tf1/lib/python3.7/traceback.py", line 497, in __init__
  File "/home/ittay.al/miniconda3/envs/tf1/lib/python3.7/traceback.py", line 497, in __init__
  File "/home/ittay.al/miniconda3/envs/tf1/lib/python3.7/traceback.py", line 497, in __init__
  File "/home/ittay.al/miniconda3/envs/tf1/lib/python3.7/traceback.py", line 508, in __init__
MemoryError

During handling of the above exception, another exception occurred:

MemoryError

During handling of the above exception, another exception occurred:

Traceback (most recent call last):
  File "/home/ittay.al/miniconda3/envs/tf1/lib/python3.7/logging/__init__.py", line 1524, in handle
MemoryError

During handling of the above exception, another exception occurred:

MemoryError

During handling of the above exception, another exception occurred:

MemoryError

During handling of the above exception, another exception occurred:

MemoryError

During handling of the above exception, another exception occurred:

MemoryError

During handling of the above exception, another exception occurred:

MemoryError

During handling of the above exception, another exception occurred:

MemoryError

During handling of the above exception, another exception occurred:

MemoryError
