Traceback (most recent call last):
  File "/home/ittay.al/venv/pproc/lib/python3.7/site-packages/angr/sim_type.py", line 46, in __init__
MemoryError

During handling of the above exception, another exception occurred:

MemoryError

During handling of the above exception, another exception occurred:

MemoryError

During handling of the above exception, another exception occurred:

Traceback (most recent call last):
  File "paths_constraints_main.py", line 5, in <module>
  File "/home/ittay.al/venv/pproc/lib/python3.7/site-packages/angr/__init__.py", line 41, in <module>
  File "/home/ittay.al/venv/pproc/lib/python3.7/site-packages/angr/procedures/__init__.py", line 2, in <module>
  File "/home/ittay.al/venv/pproc/lib/python3.7/site-packages/angr/procedures/definitions/__init__.py", line 619, in <module>
  File "/home/ittay.al/venv/pproc/lib/python3.7/site-packages/angr/misc/autoimport.py", line 40, in auto_import_modules
  File "/home/ittay.al/miniconda3/envs/tf1/lib/python3.7/importlib/__init__.py", line 127, in import_module
MemoryError
