ERROR   | 2021-12-02 02:46:14,797 | root     | b'out of memory'
ERROR   | 2021-12-02 02:46:14,797 | root     | got an error while analyzing open_possibly_compressed_file
ERROR   | 2021-12-02 02:46:29,625 | root     | b'out of memory'
ERROR   | 2021-12-02 02:46:29,625 | root     | got an error while analyzing output_dirfile
ERROR   | 2021-12-02 02:46:29,894 | root     | b'out of memory'
ERROR   | 2021-12-02 02:46:29,895 | root     | got an error while analyzing parse_input
ERROR   | 2021-12-02 02:46:30,151 | root     | b'out of memory'
ERROR   | 2021-12-02 02:46:30,151 | root     | got an error while analyzing parse_dir_file
ERROR   | 2021-12-02 02:46:33,870 | root     | b'out of memory'
ERROR   | 2021-12-02 02:46:33,870 | root     | got an error while analyzing compare_section_names
--- Logging error ---
Traceback (most recent call last):
  File "/home/ittay.al/venv/pproc/lib/python3.7/site-packages/angr/analyses/analysis.py", line 157, in _resilience
  File "/home/ittay.al/venv/pproc/lib/python3.7/site-packages/angr/analyses/loopfinder.py", line 53, in __init__
  File "/home/ittay.al/venv/pproc/lib/python3.7/site-packages/angr/knowledge_plugins/functions/function.py", line 1299, in normalize
MemoryError

During handling of the above exception, another exception occurred:

Traceback (most recent call last):
  File "paths_constraints_main.py", line 212, in analyze_binary
  File "paths_constraints_main.py", line 44, in analyze_func
  File "/home/ittay.al/venv/pproc/lib/python3.7/site-packages/angr/sim_manager.py", line 189, in use_technique
  File "/home/ittay.al/venv/pproc/lib/python3.7/site-packages/angr/exploration_techniques/loop_seer.py", line 80, in setup
  File "/home/ittay.al/venv/pproc/lib/python3.7/site-packages/angr/analyses/analysis.py", line 115, in __call__
  File "/home/ittay.al/venv/pproc/lib/python3.7/site-packages/angr/analyses/loopfinder.py", line 56, in __init__
  File "/home/ittay.al/miniconda3/envs/tf1/lib/python3.7/contextlib.py", line 130, in __exit__
  File "/home/ittay.al/venv/pproc/lib/python3.7/site-packages/angr/analyses/analysis.py", line 165, in _resilience
MemoryError

During handling of the above exception, another exception occurred:

Traceback (most recent call last):
  File "/home/ittay.al/miniconda3/envs/tf1/lib/python3.7/logging/__init__.py", line 1025, in emit
  File "/home/ittay.al/miniconda3/envs/tf1/lib/python3.7/logging/__init__.py", line 869, in format
  File "/home/ittay.al/miniconda3/envs/tf1/lib/python3.7/logging/__init__.py", line 610, in format
  File "/home/ittay.al/miniconda3/envs/tf1/lib/python3.7/logging/__init__.py", line 550, in formatTime
MemoryError
Call stack:
  File "paths_constraints_main.py", line 352, in <module>
  File "paths_constraints_main.py", line 348, in main
  File "paths_constraints_main.py", line 188, in generate_dataset
  File "paths_constraints_main.py", line 216, in analyze_binary
Message: ''
Arguments: ()
ERROR   | 2021-12-02 02:46:33,919 | root     | got an error while analyzing compare_entries_text
--- Logging error ---
Traceback (most recent call last):
  File "paths_constraints_main.py", line 212, in analyze_binary
  File "paths_constraints_main.py", line 41, in analyze_func
  File "/home/ittay.al/venv/pproc/lib/python3.7/site-packages/angr/factory.py", line 153, in call_state
  File "/home/ittay.al/venv/pproc/lib/python3.7/site-packages/angr/simos/simos.py", line 253, in state_call
  File "/home/ittay.al/venv/pproc/lib/python3.7/site-packages/angr/simos/linux.py", line 184, in state_blank
  File "/home/ittay.al/venv/pproc/lib/python3.7/site-packages/angr/storage/memory_mixins/paged_memory/stack_allocation_mixin.py", line 51, in allocate_stack_pages
  File "/home/ittay.al/venv/pproc/lib/python3.7/site-packages/angr/storage/memory_mixins/paged_memory/paged_memory_mixin.py", line 83, in _initialize_default_page
  File "/home/ittay.al/venv/pproc/lib/python3.7/site-packages/angr/storage/memory_mixins/paged_memory/paged_memory_mixin.py", line 89, in _initialize_page
  File "/home/ittay.al/venv/pproc/lib/python3.7/site-packages/angr/storage/memory_mixins/paged_memory/pages/ultra_page.py", line 30, in __init__
MemoryError

During handling of the above exception, another exception occurred:

Traceback (most recent call last):
  File "/home/ittay.al/miniconda3/envs/tf1/lib/python3.7/logging/__init__.py", line 1029, in emit
  File "/home/ittay.al/miniconda3/envs/tf1/lib/python3.7/logging/__init__.py", line 1009, in flush
MemoryError
Call stack:
  File "paths_constraints_main.py", line 352, in <module>
  File "paths_constraints_main.py", line 348, in main
  File "paths_constraints_main.py", line 188, in generate_dataset
  File "paths_constraints_main.py", line 216, in analyze_binary
Message: ''
Arguments: ()
ERROR   | 2021-12-02 02:46:33,958 | root     | got an error while analyzing mbsncasecmp
ERROR   | 2021-12-02 02:46:33,960 | root     | 
ERROR   | 2021-12-02 02:46:33,960 | root     | got an error while analyzing mbuiter_multi_next
ERROR   | 2021-12-02 02:46:33,962 | root     | 
ERROR   | 2021-12-02 02:46:33,962 | root     | got an error while analyzing mbuiter_multi_reloc
ERROR   | 2021-12-02 02:46:33,964 | root     | 
ERROR   | 2021-12-02 02:46:33,964 | root     | got an error while analyzing mbuiter_multi_copy
ERROR   | 2021-12-02 02:46:33,966 | root     | 
ERROR   | 2021-12-02 02:46:33,966 | root     | got an error while analyzing strnlen1
ERROR   | 2021-12-02 02:46:33,968 | root     | 
ERROR   | 2021-12-02 02:46:33,968 | root     | got an error while analyzing xnmalloc
ERROR   | 2021-12-02 02:46:33,970 | root     | 
ERROR   | 2021-12-02 02:46:33,970 | root     | got an error while analyzing xnrealloc
ERROR   | 2021-12-02 02:46:33,972 | root     | 
ERROR   | 2021-12-02 02:46:33,972 | root     | got an error while analyzing x2nrealloc
ERROR   | 2021-12-02 02:46:33,974 | root     | 
ERROR   | 2021-12-02 02:46:33,974 | root     | got an error while analyzing xcharalloc
ERROR   | 2021-12-02 02:46:33,976 | root     | 
ERROR   | 2021-12-02 02:46:33,977 | root     | got an error while analyzing xmalloc
ERROR   | 2021-12-02 02:46:33,978 | root     | 
ERROR   | 2021-12-02 02:46:33,979 | root     | got an error while analyzing xrealloc
ERROR   | 2021-12-02 02:46:33,981 | root     | 
ERROR   | 2021-12-02 02:46:33,981 | root     | got an error while analyzing x2realloc
ERROR   | 2021-12-02 02:46:33,983 | root     | 
ERROR   | 2021-12-02 02:46:33,983 | root     | got an error while analyzing xzalloc
ERROR   | 2021-12-02 02:46:33,985 | root     | 
ERROR   | 2021-12-02 02:46:33,985 | root     | got an error while analyzing xcalloc
ERROR   | 2021-12-02 02:46:33,987 | root     | 
ERROR   | 2021-12-02 02:46:33,987 | root     | got an error while analyzing xmemdup
ERROR   | 2021-12-02 02:46:33,989 | root     | 
ERROR   | 2021-12-02 02:46:33,989 | root     | got an error while analyzing xstrdup
ERROR   | 2021-12-02 02:46:33,991 | root     | 
ERROR   | 2021-12-02 02:46:33,991 | root     | got an error while analyzing xalloc_die
ERROR   | 2021-12-02 02:46:33,993 | root     | 
ERROR   | 2021-12-02 02:46:33,993 | root     | got an error while analyzing rpl_mbrtowc
ERROR   | 2021-12-02 02:46:33,995 | root     | 
ERROR   | 2021-12-02 02:46:33,995 | root     | got an error while analyzing hard_locale
ERROR   | 2021-12-02 02:46:33,997 | root     | 
ERROR   | 2021-12-02 02:46:33,997 | root     | got an error while analyzing mb_width_aux
ERROR   | 2021-12-02 02:46:33,999 | root     | 
ERROR   | 2021-12-02 02:46:33,999 | root     | got an error while analyzing mb_copy
ERROR   | 2021-12-02 02:46:34,002 | root     | 
ERROR   | 2021-12-02 02:46:34,002 | root     | got an error while analyzing is_basic
