ERROR   | 2021-12-02 03:55:43,282 | root     | b'out of memory'
ERROR   | 2021-12-02 03:55:43,283 | root     | got an error while analyzing uvwrite_taylor_system
ERROR   | 2021-12-02 03:55:45,989 | root     | b'out of memory'
ERROR   | 2021-12-02 03:55:45,989 | root     | got an error while analyzing uvwrite_v2_system
ERROR   | 2021-12-02 03:55:49,014 | root     | b'out of memory'
ERROR   | 2021-12-02 03:55:49,014 | root     | got an error while analyzing uvwrite_hdb_system
ERROR   | 2021-12-02 03:55:58,960 | root     | b'out of memory'
ERROR   | 2021-12-02 03:55:58,960 | root     | got an error while analyzing uvadd_perm
ERROR   | 2021-12-02 03:56:08,218 | root     | b'out of memory'
ERROR   | 2021-12-02 03:56:08,218 | root     | got an error while analyzing uvwrite_perm_array
--- Logging error ---
Traceback (most recent call last):
  File "/home/ittay.al/venv/pproc/lib/python3.7/site-packages/angr/analyses/analysis.py", line 157, in _resilience
  File "/home/ittay.al/venv/pproc/lib/python3.7/site-packages/angr/analyses/loopfinder.py", line 54, in __init__
  File "/home/ittay.al/venv/pproc/lib/python3.7/site-packages/angr/analyses/loopfinder.py", line 163, in _parse_loops_from_graph
  File "/home/ittay.al/venv/pproc/lib/python3.7/site-packages/angr/analyses/loopfinder.py", line 163, in <genexpr>
  File "/home/ittay.al/venv/pproc/lib/python3.7/site-packages/networkx/classes/function.py", line 393, in induced_subgraph
  File "/home/ittay.al/venv/pproc/lib/python3.7/site-packages/networkx/classes/graphviews.py", line 144, in subgraph_view
  File "/home/ittay.al/venv/pproc/lib/python3.7/site-packages/networkx/classes/digraph.py", line 301, in __init__
MemoryError

During handling of the above exception, another exception occurred:

Traceback (most recent call last):
  File "paths_constraints_main.py", line 212, in analyze_binary
  File "paths_constraints_main.py", line 44, in analyze_func
  File "/home/ittay.al/venv/pproc/lib/python3.7/site-packages/angr/sim_manager.py", line 189, in use_technique
  File "/home/ittay.al/venv/pproc/lib/python3.7/site-packages/angr/exploration_techniques/loop_seer.py", line 80, in setup
  File "/home/ittay.al/venv/pproc/lib/python3.7/site-packages/angr/analyses/analysis.py", line 115, in __call__
  File "/home/ittay.al/venv/pproc/lib/python3.7/site-packages/angr/analyses/loopfinder.py", line 56, in __init__
  File "/home/ittay.al/miniconda3/envs/tf1/lib/python3.7/contextlib.py", line 130, in __exit__
  File "/home/ittay.al/venv/pproc/lib/python3.7/site-packages/angr/analyses/analysis.py", line 162, in _resilience
MemoryError

During handling of the above exception, another exception occurred:

Traceback (most recent call last):
  File "/home/ittay.al/miniconda3/envs/tf1/lib/python3.7/logging/__init__.py", line 1025, in emit
  File "/home/ittay.al/miniconda3/envs/tf1/lib/python3.7/logging/__init__.py", line 869, in format
  File "/home/ittay.al/miniconda3/envs/tf1/lib/python3.7/logging/__init__.py", line 610, in format
  File "/home/ittay.al/miniconda3/envs/tf1/lib/python3.7/logging/__init__.py", line 550, in formatTime
MemoryError

During handling of the above exception, another exception occurred:

Traceback (most recent call last):
  File "paths_constraints_main.py", line 352, in <module>
  File "paths_constraints_main.py", line 348, in main
  File "paths_constraints_main.py", line 188, in generate_dataset
  File "paths_constraints_main.py", line 216, in analyze_binary
  File "/home/ittay.al/miniconda3/envs/tf1/lib/python3.7/logging/__init__.py", line 1959, in error
  File "/home/ittay.al/miniconda3/envs/tf1/lib/python3.7/logging/__init__.py", line 1407, in error
  File "/home/ittay.al/miniconda3/envs/tf1/lib/python3.7/logging/__init__.py", line 1514, in _log
  File "/home/ittay.al/miniconda3/envs/tf1/lib/python3.7/logging/__init__.py", line 1524, in handle
  File "/home/ittay.al/miniconda3/envs/tf1/lib/python3.7/logging/__init__.py", line 1586, in callHandlers
  File "/home/ittay.al/miniconda3/envs/tf1/lib/python3.7/logging/__init__.py", line 894, in handle
  File "/home/ittay.al/miniconda3/envs/tf1/lib/python3.7/logging/__init__.py", line 1033, in emit
  File "/home/ittay.al/miniconda3/envs/tf1/lib/python3.7/logging/__init__.py", line 947, in handleError
  File "/home/ittay.al/miniconda3/envs/tf1/lib/python3.7/traceback.py", line 104, in print_exception
  File "/home/ittay.al/miniconda3/envs/tf1/lib/python3.7/traceback.py", line 497, in __init__
  File "/home/ittay.al/miniconda3/envs/tf1/lib/python3.7/traceback.py", line 497, in __init__
  File "/home/ittay.al/miniconda3/envs/tf1/lib/python3.7/traceback.py", line 508, in __init__
MemoryError
