ERROR   | 2021-12-02 04:26:09,529 | root     | list index out of range
ERROR   | 2021-12-02 04:26:09,530 | root     | got an error while analyzing ldtoastr
ERROR   | 2021-12-02 04:38:47,320 | root     | argument 3: <class 'RecursionError'>: maximum recursion depth exceeded in __instancecheck__
ERROR   | 2021-12-02 04:38:47,320 | root     | got an error while analyzing xstrtoumax
ERROR   | 2021-12-02 04:39:20,782 | root     | b'out of memory'
ERROR   | 2021-12-02 04:39:20,782 | root     | got an error while analyzing get_charset_aliases
ERROR   | 2021-12-02 04:39:22,156 | root     | b'out of memory'
ERROR   | 2021-12-02 04:39:22,156 | root     | got an error while analyzing locale_charset
ERROR   | 2021-12-02 04:39:24,778 | root     | 
ERROR   | 2021-12-02 04:39:24,778 | root     | got an error while analyzing c_isalpha
ERROR   | 2021-12-02 04:39:24,793 | root     | 
ERROR   | 2021-12-02 04:39:24,793 | root     | got an error while analyzing c_isascii
ERROR   | 2021-12-02 04:39:24,804 | root     | 
ERROR   | 2021-12-02 04:39:24,804 | root     | got an error while analyzing c_isblank
--- Logging error ---
Traceback (most recent call last):
  File "paths_constraints_main.py", line 212, in analyze_binary
  File "paths_constraints_main.py", line 41, in analyze_func
  File "/home/ittay.al/venv/pproc/lib/python3.7/site-packages/angr/factory.py", line 153, in call_state
  File "/home/ittay.al/venv/pproc/lib/python3.7/site-packages/angr/simos/simos.py", line 253, in state_call
  File "/home/ittay.al/venv/pproc/lib/python3.7/site-packages/angr/simos/linux.py", line 184, in state_blank
  File "/home/ittay.al/venv/pproc/lib/python3.7/site-packages/angr/storage/memory_mixins/paged_memory/stack_allocation_mixin.py", line 51, in allocate_stack_pages
  File "/home/ittay.al/venv/pproc/lib/python3.7/site-packages/angr/storage/memory_mixins/paged_memory/paged_memory_mixin.py", line 83, in _initialize_default_page
  File "/home/ittay.al/venv/pproc/lib/python3.7/site-packages/angr/storage/memory_mixins/paged_memory/paged_memory_mixin.py", line 89, in _initialize_page
  File "/home/ittay.al/venv/pproc/lib/python3.7/site-packages/angr/storage/memory_mixins/paged_memory/pages/ultra_page.py", line 30, in __init__
MemoryError

During handling of the above exception, another exception occurred:

Traceback (most recent call last):
  File "/home/ittay.al/miniconda3/envs/tf1/lib/python3.7/logging/__init__.py", line 1025, in emit
  File "/home/ittay.al/miniconda3/envs/tf1/lib/python3.7/logging/__init__.py", line 869, in format
  File "/home/ittay.al/miniconda3/envs/tf1/lib/python3.7/logging/__init__.py", line 610, in format
  File "/home/ittay.al/miniconda3/envs/tf1/lib/python3.7/logging/__init__.py", line 550, in formatTime
MemoryError
Call stack:
  File "paths_constraints_main.py", line 352, in <module>
  File "paths_constraints_main.py", line 348, in main
  File "paths_constraints_main.py", line 188, in generate_dataset
  File "paths_constraints_main.py", line 216, in analyze_binary
Message: ''
Arguments: ()
ERROR   | 2021-12-02 04:39:24,827 | root     | got an error while analyzing c_iscntrl
Traceback (most recent call last):
  File "paths_constraints_main.py", line 212, in analyze_binary
  File "paths_constraints_main.py", line 41, in analyze_func
  File "/home/ittay.al/venv/pproc/lib/python3.7/site-packages/angr/factory.py", line 153, in call_state
  File "/home/ittay.al/venv/pproc/lib/python3.7/site-packages/angr/simos/simos.py", line 253, in state_call
  File "/home/ittay.al/venv/pproc/lib/python3.7/site-packages/angr/simos/linux.py", line 184, in state_blank
  File "/home/ittay.al/venv/pproc/lib/python3.7/site-packages/angr/storage/memory_mixins/paged_memory/stack_allocation_mixin.py", line 51, in allocate_stack_pages
  File "/home/ittay.al/venv/pproc/lib/python3.7/site-packages/angr/storage/memory_mixins/paged_memory/paged_memory_mixin.py", line 83, in _initialize_default_page
  File "/home/ittay.al/venv/pproc/lib/python3.7/site-packages/angr/storage/memory_mixins/paged_memory/paged_memory_mixin.py", line 89, in _initialize_page
  File "/home/ittay.al/venv/pproc/lib/python3.7/site-packages/angr/storage/memory_mixins/paged_memory/pages/ultra_page.py", line 30, in __init__
MemoryError

During handling of the above exception, another exception occurred:

Traceback (most recent call last):
  File "/home/ittay.al/miniconda3/envs/tf1/lib/python3.7/logging/__init__.py", line 1025, in emit
  File "/home/ittay.al/miniconda3/envs/tf1/lib/python3.7/logging/__init__.py", line 869, in format
  File "/home/ittay.al/miniconda3/envs/tf1/lib/python3.7/logging/__init__.py", line 610, in format
  File "/home/ittay.al/miniconda3/envs/tf1/lib/python3.7/logging/__init__.py", line 550, in formatTime
MemoryError

During handling of the above exception, another exception occurred:

Traceback (most recent call last):
  File "paths_constraints_main.py", line 352, in <module>
  File "paths_constraints_main.py", line 348, in main
  File "paths_constraints_main.py", line 188, in generate_dataset
  File "paths_constraints_main.py", line 216, in analyze_binary
  File "/home/ittay.al/miniconda3/envs/tf1/lib/python3.7/logging/__init__.py", line 1959, in error
  File "/home/ittay.al/miniconda3/envs/tf1/lib/python3.7/logging/__init__.py", line 1407, in error
  File "/home/ittay.al/miniconda3/envs/tf1/lib/python3.7/logging/__init__.py", line 1514, in _log
  File "/home/ittay.al/miniconda3/envs/tf1/lib/python3.7/logging/__init__.py", line 1524, in handle
  File "/home/ittay.al/miniconda3/envs/tf1/lib/python3.7/logging/__init__.py", line 1586, in callHandlers
  File "/home/ittay.al/miniconda3/envs/tf1/lib/python3.7/logging/__init__.py", line 894, in handle
  File "/home/ittay.al/miniconda3/envs/tf1/lib/python3.7/logging/__init__.py", line 1033, in emit
  File "/home/ittay.al/miniconda3/envs/tf1/lib/python3.7/logging/__init__.py", line 947, in handleError
  File "/home/ittay.al/miniconda3/envs/tf1/lib/python3.7/traceback.py", line 105, in print_exception
MemoryError
