--- Logging error ---
Traceback (most recent call last):
  File "/home/ittay.al/venv/pproc/lib/python3.7/site-packages/angr/analyses/analysis.py", line 157, in _resilience
  File "/home/ittay.al/venv/pproc/lib/python3.7/site-packages/angr/analyses/loopfinder.py", line 54, in __init__
  File "/home/ittay.al/venv/pproc/lib/python3.7/site-packages/angr/analyses/loopfinder.py", line 163, in _parse_loops_from_graph
  File "/home/ittay.al/venv/pproc/lib/python3.7/site-packages/angr/analyses/loopfinder.py", line 163, in <genexpr>
  File "<class 'networkx.utils.decorators.argmap'> compilation 8", line 4, in argmap_strongly_connected_components_5
  File "/home/ittay.al/venv/pproc/lib/python3.7/site-packages/networkx/algorithms/components/strongly_connected.py", line 74, in strongly_connected_components
MemoryError

During handling of the above exception, another exception occurred:

Traceback (most recent call last):
  File "paths_constraints_main.py", line 213, in analyze_binary
  File "paths_constraints_main.py", line 45, in analyze_func
  File "/home/ittay.al/venv/pproc/lib/python3.7/site-packages/angr/sim_manager.py", line 189, in use_technique
  File "/home/ittay.al/venv/pproc/lib/python3.7/site-packages/angr/exploration_techniques/loop_seer.py", line 80, in setup
  File "/home/ittay.al/venv/pproc/lib/python3.7/site-packages/angr/analyses/analysis.py", line 115, in __call__
  File "/home/ittay.al/venv/pproc/lib/python3.7/site-packages/angr/analyses/loopfinder.py", line 56, in __init__
  File "/home/ittay.al/miniconda3/envs/tf1/lib/python3.7/contextlib.py", line 130, in __exit__
  File "/home/ittay.al/venv/pproc/lib/python3.7/site-packages/angr/analyses/analysis.py", line 162, in _resilience
MemoryError

During handling of the above exception, another exception occurred:

Traceback (most recent call last):
  File "/home/ittay.al/miniconda3/envs/tf1/lib/python3.7/logging/__init__.py", line 1025, in emit
  File "/home/ittay.al/miniconda3/envs/tf1/lib/python3.7/logging/__init__.py", line 869, in format
  File "/home/ittay.al/miniconda3/envs/tf1/lib/python3.7/logging/__init__.py", line 610, in format
  File "/home/ittay.al/miniconda3/envs/tf1/lib/python3.7/logging/__init__.py", line 550, in formatTime
MemoryError

During handling of the above exception, another exception occurred:

Traceback (most recent call last):
  File "paths_constraints_main.py", line 355, in <module>
  File "paths_constraints_main.py", line 351, in main
  File "paths_constraints_main.py", line 189, in generate_dataset
  File "paths_constraints_main.py", line 217, in analyze_binary
  File "/home/ittay.al/miniconda3/envs/tf1/lib/python3.7/logging/__init__.py", line 1959, in error
  File "/home/ittay.al/miniconda3/envs/tf1/lib/python3.7/logging/__init__.py", line 1407, in error
  File "/home/ittay.al/miniconda3/envs/tf1/lib/python3.7/logging/__init__.py", line 1514, in _log
  File "/home/ittay.al/miniconda3/envs/tf1/lib/python3.7/logging/__init__.py", line 1524, in handle
  File "/home/ittay.al/miniconda3/envs/tf1/lib/python3.7/logging/__init__.py", line 1586, in callHandlers
  File "/home/ittay.al/miniconda3/envs/tf1/lib/python3.7/logging/__init__.py", line 894, in handle
  File "/home/ittay.al/miniconda3/envs/tf1/lib/python3.7/logging/__init__.py", line 1033, in emit
  File "/home/ittay.al/miniconda3/envs/tf1/lib/python3.7/logging/__init__.py", line 947, in handleError
  File "/home/ittay.al/miniconda3/envs/tf1/lib/python3.7/traceback.py", line 104, in print_exception
  File "/home/ittay.al/miniconda3/envs/tf1/lib/python3.7/traceback.py", line 497, in __init__
  File "/home/ittay.al/miniconda3/envs/tf1/lib/python3.7/traceback.py", line 508, in __init__
  File "/home/ittay.al/miniconda3/envs/tf1/lib/python3.7/traceback.py", line 350, in extract
  File "/home/ittay.al/miniconda3/envs/tf1/lib/python3.7/linecache.py", line 175, in lazycache
MemoryError
