ERROR   | 2021-12-02 19:44:48,802 | root     | 
ERROR   | 2021-12-02 19:44:48,803 | root     | got an error while analyzing deregister_tm_clones
--- Logging error ---
Traceback (most recent call last):
  File "paths_constraints_main.py", line 213, in analyze_binary
  File "paths_constraints_main.py", line 42, in analyze_func
  File "/home/ittay.al/venv/pproc/lib/python3.7/site-packages/angr/factory.py", line 153, in call_state
  File "/home/ittay.al/venv/pproc/lib/python3.7/site-packages/angr/simos/simos.py", line 253, in state_call
  File "/home/ittay.al/venv/pproc/lib/python3.7/site-packages/angr/simos/linux.py", line 184, in state_blank
  File "/home/ittay.al/venv/pproc/lib/python3.7/site-packages/angr/storage/memory_mixins/paged_memory/stack_allocation_mixin.py", line 51, in allocate_stack_pages
  File "/home/ittay.al/venv/pproc/lib/python3.7/site-packages/angr/storage/memory_mixins/paged_memory/paged_memory_mixin.py", line 83, in _initialize_default_page
    return PagedMemoryMixin._initialize_page(self, pageno, permissions=permissions, **kwargs)
  File "/home/ittay.al/venv/pproc/lib/python3.7/site-packages/angr/storage/memory_mixins/paged_memory/paged_memory_mixin.py", line 89, in _initialize_page
    return self.PAGE_TYPE(**self._page_kwargs(pageno, permissions))  # pylint:disable=not-callable
  File "/home/ittay.al/venv/pproc/lib/python3.7/site-packages/angr/storage/memory_mixins/paged_memory/pages/ultra_page.py", line 30, in __init__
    self.symbolic_bitmap = bytearray(b'\1'*memory.page_size)
MemoryError

During handling of the above exception, another exception occurred:

Traceback (most recent call last):
  File "/home/ittay.al/miniconda3/envs/tf1/lib/python3.7/logging/__init__.py", line 1025, in emit
  File "/home/ittay.al/miniconda3/envs/tf1/lib/python3.7/logging/__init__.py", line 869, in format
  File "/home/ittay.al/miniconda3/envs/tf1/lib/python3.7/logging/__init__.py", line 610, in format
  File "/home/ittay.al/miniconda3/envs/tf1/lib/python3.7/logging/__init__.py", line 550, in formatTime
MemoryError
Call stack:
  File "paths_constraints_main.py", line 355, in <module>
    main()
  File "paths_constraints_main.py", line 351, in main
    generate_dataset(binaries[args.binary_idx], args.output, args.dataset, args.no_usables_file)
  File "paths_constraints_main.py", line 189, in generate_dataset
    analyze_binary(analyzed_funcs, train_binary, output_dir, is_function_usable)
  File "paths_constraints_main.py", line 217, in analyze_binary
    logging.error(str(e))
Message: ''
Arguments: ()
ERROR   | 2021-12-02 19:44:48,838 | root     | got an error while analyzing register_tm_clones
