ERROR   | 2021-12-02 20:39:21,017 | root     | 
ERROR   | 2021-12-02 20:39:21,165 | root     | got an error while analyzing concatenate_arguments
ERROR   | 2021-12-02 21:09:03,103 | root     | 
ERROR   | 2021-12-02 21:09:03,107 | root     | got an error while analyzing daemon_commandtoken_escape
ERROR   | 2021-12-02 21:20:41,653 | root     | 
ERROR   | 2021-12-02 21:20:41,656 | root     | got an error while analyzing daemon_commandtoken_escape_string
ERROR   | 2021-12-02 23:35:40,630 | root     | b'out of memory'
ERROR   | 2021-12-02 23:35:40,631 | root     | got an error while analyzing parse_host_data
Exception ignored in: <generator object FunctionManager.__iter__ at 0x7f2c5baa69d0>
MemoryError: 
Exception ignored in: <generator object ValuesView.__iter__ at 0x7f2c5baa6750>
MemoryError: 
ERROR   | 2021-12-02 23:35:42,849 | root     | 
ERROR   | 2021-12-02 23:35:42,850 | root     | got an error while analyzing remote_shell_init
Traceback (most recent call last):
  File "/home/ittay.al/venv/pproc/lib/python3.7/site-packages/angr/factory.py", line 153, in call_state
  File "/home/ittay.al/venv/pproc/lib/python3.7/site-packages/angr/simos/simos.py", line 253, in state_call
  File "/home/ittay.al/venv/pproc/lib/python3.7/site-packages/angr/simos/linux.py", line 180, in state_blank
  File "/home/ittay.al/venv/pproc/lib/python3.7/site-packages/angr/simos/simos.py", line 142, in state_blank
  File "/home/ittay.al/venv/pproc/lib/python3.7/site-packages/angr/sim_state.py", line 191, in __init__
  File "/home/ittay.al/venv/pproc/lib/python3.7/site-packages/angr/storage/memory_mixins/underconstrained_mixin.py", line 11, in __init__
  File "/home/ittay.al/venv/pproc/lib/python3.7/site-packages/angr/storage/memory_mixins/size_resolution_mixin.py", line 62, in __init__
MemoryError

During handling of the above exception, another exception occurred:

MemoryError

During handling of the above exception, another exception occurred:

MemoryError

During handling of the above exception, another exception occurred:

MemoryError

During handling of the above exception, another exception occurred:

MemoryError

During handling of the above exception, another exception occurred:

MemoryError

During handling of the above exception, another exception occurred:

MemoryError

During handling of the above exception, another exception occurred:

MemoryError

During handling of the above exception, another exception occurred:

MemoryError

During handling of the above exception, another exception occurred:

MemoryError

During handling of the above exception, another exception occurred:

MemoryError

During handling of the above exception, another exception occurred:

MemoryError
