ERROR   | 2021-11-30 15:54:17,553 | root     | list index out of range
ERROR   | 2021-11-30 15:54:17,553 | root     | got an error while analyzing finalize_numeric_output_buffer
ERROR   | 2021-11-30 15:54:28,056 | root     | list index out of range
ERROR   | 2021-11-30 15:54:28,056 | root     | got an error while analyzing is_zero
ERROR   | 2021-11-30 15:54:28,590 | root     | list index out of range
ERROR   | 2021-11-30 15:54:28,590 | root     | got an error while analyzing is_signed_zero
ERROR   | 2021-11-30 15:54:31,704 | root     | list index out of range
ERROR   | 2021-11-30 15:54:31,704 | root     | got an error while analyzing cmp_long_double
ERROR   | 2021-11-30 15:54:32,324 | root     | list index out of range
ERROR   | 2021-11-30 15:54:32,324 | root     | got an error while analyzing median_value
ERROR   | 2021-11-30 15:56:28,740 | root     | list index out of range
ERROR   | 2021-11-30 15:56:28,741 | root     | got an error while analyzing percentile_value
ERROR   | 2021-11-30 15:56:29,855 | root     | list index out of range
ERROR   | 2021-11-30 15:56:29,855 | root     | got an error while analyzing mad_value
ERROR   | 2021-11-30 15:56:30,918 | root     | list index out of range
ERROR   | 2021-11-30 15:56:30,918 | root     | got an error while analyzing arithmetic_mean_value
ERROR   | 2021-11-30 15:56:31,998 | root     | list index out of range
ERROR   | 2021-11-30 15:56:31,998 | root     | got an error while analyzing variance_value
ERROR   | 2021-11-30 15:56:33,078 | root     | list index out of range
ERROR   | 2021-11-30 15:56:33,078 | root     | got an error while analyzing covariance_value
ERROR   | 2021-11-30 15:56:34,146 | root     | list index out of range
ERROR   | 2021-11-30 15:56:34,147 | root     | got an error while analyzing pearson_corr_value
ERROR   | 2021-11-30 15:56:36,299 | root     | list index out of range
ERROR   | 2021-11-30 15:56:36,300 | root     | got an error while analyzing stdev_value
ERROR   | 2021-11-30 15:56:37,352 | root     | list index out of range
ERROR   | 2021-11-30 15:56:37,352 | root     | got an error while analyzing skewness_value
ERROR   | 2021-11-30 15:56:39,952 | root     | list index out of range
ERROR   | 2021-11-30 15:56:39,953 | root     | got an error while analyzing SES_value
ERROR   | 2021-11-30 15:56:41,072 | root     | list index out of range
ERROR   | 2021-11-30 15:56:41,073 | root     | got an error while analyzing skewnessZ_value
ERROR   | 2021-11-30 15:56:42,180 | root     | list index out of range
ERROR   | 2021-11-30 15:56:42,180 | root     | got an error while analyzing excess_kurtosis_value
ERROR   | 2021-11-30 15:56:43,288 | root     | list index out of range
ERROR   | 2021-11-30 15:56:43,288 | root     | got an error while analyzing SEK_value
ERROR   | 2021-11-30 15:56:44,091 | root     | list index out of range
ERROR   | 2021-11-30 15:56:44,091 | root     | got an error while analyzing kurtosisZ_value
ERROR   | 2021-11-30 15:56:45,591 | root     | list index out of range
ERROR   | 2021-11-30 15:56:45,592 | root     | got an error while analyzing pchisq_df2
ERROR   | 2021-11-30 15:56:46,302 | root     | list index out of range
ERROR   | 2021-11-30 15:56:46,302 | root     | got an error while analyzing jarque_bera_pvalue
ERROR   | 2021-11-30 15:56:47,352 | root     | list index out of range
ERROR   | 2021-11-30 15:56:47,352 | root     | got an error while analyzing dagostino_pearson_omnibus_pvalue
ERROR   | 2021-11-30 15:56:48,363 | root     | list index out of range
ERROR   | 2021-11-30 15:56:48,363 | root     | got an error while analyzing mode_value
ERROR   | 2021-11-30 15:56:49,395 | root     | list index out of range
ERROR   | 2021-11-30 15:56:49,396 | root     | got an error while analyzing trimmed_mean_value
ERROR   | 2021-11-30 16:03:27,226 | root     | argument 3: <class 'RecursionError'>: maximum recursion depth exceeded in __instancecheck__
ERROR   | 2021-11-30 16:03:27,227 | root     | got an error while analyzing parse_operations
ERROR   | 2021-11-30 16:04:44,668 | root     | list index out of range
ERROR   | 2021-11-30 16:04:44,668 | root     | got an error while analyzing quartile1_value
ERROR   | 2021-11-30 16:04:45,216 | root     | list index out of range
ERROR   | 2021-11-30 16:04:45,216 | root     | got an error while analyzing quartile3_value
ERROR   | 2021-11-30 16:04:46,621 | root     | list index out of range
ERROR   | 2021-11-30 16:04:46,621 | root     | got an error while analyzing field_op_add_value
ERROR   | 2021-11-30 16:05:41,623 | root     | list index out of range
ERROR   | 2021-11-30 16:05:41,624 | root     | got an error while analyzing field_op_collect
ERROR   | 2021-11-30 16:06:39,921 | root     | list index out of range
ERROR   | 2021-11-30 16:06:39,921 | root     | got an error while analyzing field_op_summarize_empty
ERROR   | 2021-11-30 16:06:40,458 | root     | list index out of range
ERROR   | 2021-11-30 16:06:40,459 | root     | got an error while analyzing field_op_summarize
ERROR   | 2021-11-30 16:06:41,384 | root     | list index out of range
ERROR   | 2021-11-30 16:06:41,384 | root     | got an error while analyzing field_op_reset
ERROR   | 2021-11-30 16:32:41,912 | root     | b'out of memory'
ERROR   | 2021-11-30 16:32:41,913 | root     | got an error while analyzing print_column_headers
--- Logging error ---
Traceback (most recent call last):
  File "/home/ittay.al/venv/pproc/lib/python3.7/site-packages/angr/analyses/analysis.py", line 157, in _resilience
  File "/home/ittay.al/venv/pproc/lib/python3.7/site-packages/angr/analyses/loopfinder.py", line 54, in __init__
  File "/home/ittay.al/venv/pproc/lib/python3.7/site-packages/angr/analyses/loopfinder.py", line 163, in _parse_loops_from_graph
  File "/home/ittay.al/venv/pproc/lib/python3.7/site-packages/angr/analyses/loopfinder.py", line 163, in <genexpr>
  File "/home/ittay.al/venv/pproc/lib/python3.7/site-packages/networkx/classes/function.py", line 393, in induced_subgraph
  File "/home/ittay.al/venv/pproc/lib/python3.7/site-packages/networkx/classes/graphviews.py", line 144, in subgraph_view
MemoryError

During handling of the above exception, another exception occurred:

Traceback (most recent call last):
  File "paths_constraints_main.py", line 212, in analyze_binary
  File "paths_constraints_main.py", line 44, in analyze_func
  File "/home/ittay.al/venv/pproc/lib/python3.7/site-packages/angr/sim_manager.py", line 189, in use_technique
  File "/home/ittay.al/venv/pproc/lib/python3.7/site-packages/angr/exploration_techniques/loop_seer.py", line 80, in setup
  File "/home/ittay.al/venv/pproc/lib/python3.7/site-packages/angr/analyses/analysis.py", line 115, in __call__
  File "/home/ittay.al/venv/pproc/lib/python3.7/site-packages/angr/analyses/loopfinder.py", line 56, in __init__
  File "/home/ittay.al/miniconda3/envs/tf1/lib/python3.7/contextlib.py", line 130, in __exit__
  File "/home/ittay.al/venv/pproc/lib/python3.7/site-packages/angr/analyses/analysis.py", line 162, in _resilience
MemoryError

During handling of the above exception, another exception occurred:

Traceback (most recent call last):
  File "/home/ittay.al/miniconda3/envs/tf1/lib/python3.7/logging/__init__.py", line 1025, in emit
  File "/home/ittay.al/miniconda3/envs/tf1/lib/python3.7/logging/__init__.py", line 869, in format
  File "/home/ittay.al/miniconda3/envs/tf1/lib/python3.7/logging/__init__.py", line 610, in format
  File "/home/ittay.al/miniconda3/envs/tf1/lib/python3.7/logging/__init__.py", line 550, in formatTime
MemoryError

During handling of the above exception, another exception occurred:

Traceback (most recent call last):
  File "/home/ittay.al/miniconda3/envs/tf1/lib/python3.7/traceback.py", line 508, in __init__
  File "/home/ittay.al/miniconda3/envs/tf1/lib/python3.7/traceback.py", line 350, in extract
  File "/home/ittay.al/miniconda3/envs/tf1/lib/python3.7/linecache.py", line 175, in lazycache
MemoryError

During handling of the above exception, another exception occurred:

MemoryError

During handling of the above exception, another exception occurred:

MemoryError

During handling of the above exception, another exception occurred:

MemoryError

During handling of the above exception, another exception occurred:

MemoryError

During handling of the above exception, another exception occurred:

MemoryError

During handling of the above exception, another exception occurred:

Traceback (most recent call last):
  File "/home/ittay.al/miniconda3/envs/tf1/lib/python3.7/logging/__init__.py", line 1524, in handle
MemoryError

During handling of the above exception, another exception occurred:

MemoryError

During handling of the above exception, another exception occurred:

MemoryError

During handling of the above exception, another exception occurred:

MemoryError

During handling of the above exception, another exception occurred:

MemoryError

During handling of the above exception, another exception occurred:

MemoryError

During handling of the above exception, another exception occurred:

MemoryError

During handling of the above exception, another exception occurred:

MemoryError
